Workbook

Sheet Cover
C2: GATX Corporation: Financial Statement Model
C3: $ mm except per share
C5: Company name | D5: GATX Corporation
C6: Ticker | D6: GATX
C7: Circ break 1=off, 0=on (no circular interest in this build) | D7: 1
C8: Latest closing share price | D8: =Drivers!C179 -> 162.78
C9: Share price date | D9: 46303
C10: Latest fiscal year end | D10: 46022
C11: Shares outstanding (millions, diluted 2026E) | D11: =Drivers!C77 -> 35.8
A13: x | C13: CONTENTS
C14: Sheet | D14: No. | E14: What it does
C15: Cover | D15: 1 | E15: This sheet: contents, version log, checks, rating, sources
C16: Drivers | D16: 2 | E16: All inputs (blue) + assumptions + derived cells with citation column
C17: Historicals | D17: 3 | E17: 5-6 years IS + BS from FY2020-2025 10-Ks, each year cited to its own filing
C18: 3 Statement Forecast | D18: 4 | E18: Full IS/BS/CFS 2025A-2035E, revolver-plug cash mechanic, balance check row 62
C19: Debt & Interest | D19: 5 | E19: Q2 2026 10-Q maturity ladder rolled forward; interest by fixed/floating buckets
C20: Legacy Cohort Model | D20: 6 | E20: 5 vintage cohorts (2021-2025) + base fleet, rate compounds at Terminal_LPI in 2031E+
C21: Acquired Pool | D21: 7 | E21: Wells Fargo pool (98,535 cars); blended rate reprices expiring fraction at LPI
C22: GABX Mini P&L | D22: 8 | E22: JV P&L direct from 10-Q Note 7; ownership steps 30% → 33.5% → +7%/tranche
C23: Segment P&L | D23: 9 | E23: Rail NA / Rail Intl / Engine Leasing / Other rollup into consolidated revenue
C24: Disposition Engine | D24: 10 | E24: Cars sold + scrapped × gain-per-car; 2026 legacy dispo tied to guidance
C25: Thesis Test | D25: 11 | E25: Sources vs uses grid; LPI × new-issue-rate sensitivity; kill-criterion tests
C26: Valuation | D26: 12 | E26: P/E scenario weighting (bear/base/bull) → probability-weighted target price
... C36: Summary | D36: 22 | E36: Headline summary table; error-cell check
A38: x | C38: VERSION LOG
C39: Version | D39: Date | E39: What changed
C40: v1 | D40: 2026-09-24 | E40: Initial IS build; 2025A from FY2025 10-K
C41: v2 | D41: 2026-09-24 | E41: BS added; historical years cited to their own 10-Ks
C42: v3 | D42: 2026-09-24 | E42: CFS added; revolver plug; balance check row
C43: v4 | D43: 2026-09-24 | E43: Legacy Cohort Model added; 5 vintages + base fleet
C44: v5 | D44: 2026-09-24 | E44: Acquired Pool (Wells Fargo) added
C45: v6 | D45: 2026-09-24 | E45: Full rebuild per user rules (no removal, no invention, WF in 2026 CFI)
C46: v7 | D46: 2026-09-24 | E46: Fixed/floating debt split; interest by bucket per 10-Q p.42
C47: v8 | D47: 2026-09-24 | E47: Valuation inputs (v8): FactSet peers, NTM P/E, dividend yield
C48: v9 | D48: 2026-09-25 | E48: Sections 1-3: dispositions engine, GABX ownership/fees, 2028-2030 extension
C49: v10 | D49: 2026-09-25 | E49: Fix 1: Rail NA other rev anchored $160M (no fee double-count); Fix 3: dispo reconciliation
C50: v11 | D50: 2026-09-25 | E50: GABX P&L build refined; Note 7 direct link
... C61: v23 | D61: 2026-09-28 | E61: Terminal state 2031E-2035E rebuilt bottom-up (Terminal_LPI 2%, Terminal_fleet_growth 1%, D&A from PP&E/life, capex per WO with 15% taper, D/(D+E) target-held); Cover rebuilt in WSP layout
A63: x | C63: CHECKS SUMMARY (at-a-glance workbook health)
C64: Check | D64: Value | E64: Target / Source
...

Sheet Drivers
B1: GATX FSM v6 — DRIVERS (blue = input; source on every row)
B3: Driver | C3: Value | O3: Source
A4: x | B4: --- FLEET ---
B5: RailNA_ex_boxcars_YE2025 | C5: 100593 | O5: FY2025 10-K p.31: Rail NA railcars ex-boxcars ending 100,593
B6: RailNA_boxcars_YE2025 | C6: 7032 | O6: FY2025 10-K p.33: boxcars ending 7,032
B7: RailNA_utilization_YE2025 | C7: 0.99 | O7: FY2025 10-K p.31: 99.0% ex-boxcars
B8: RailNA_renewal_success_2025 | C8: 0.873 | O8: FY2025 10-K p.31: 87.3%
B9: LPI_FY2025 | C9: 0.219 | O9: FY2025 10-K p.32: +21.9%
A10: x | B10: --- LEGACY COHORTS (5 vintages) ---
B11: Cohort_2021_cars | C11: 20000 | O11: Company Overview deck p.30 (2021 renewal count)
B12: Cohort_2022_cars | C12: 18500 | O12: Deck p.30
B13: Cohort_2023_cars | C13: 18700 | O13: Deck p.30
B14: Cohort_2024_cars | C14: 19400 | O14: Deck p.30
B15: Cohort_2025_cars | C15: 21500 | O15: FY2025 10-K p.31 (21,500 renewed FY2025)
B16: Legacy_base_fleet_cars | C16: 2493 | O16: Derived: 100,593 ex-boxcars − 5 cohorts × 98,100
B17: Cohort_2021_rate_pre | C17: 6800 | O17: Assumption: 2021 vintage low (LPI down cycle 2016-21)
B18: Cohort_2022_rate_pre | C18: 7200 | O18: Assumption: modest recovery
B19: Cohort_2023_rate_pre | C19: 7500 | O19: Assumption: continued recovery
B20: Cohort_2024_rate_pre | C20: 7900 | O20: Assumption
B21: Cohort_2025_rate_pre | C21: 8100 | O21: Assumption: near current avg
B22: Legacy_base_rate | C22: 8300 | O22: Assumption: base fleet at current avg
B23: Cohort_calibration_factor (RETIRED v36) | C23: 1.2387 | D23: v36 2026-10-07: RETIRED. New engine on Legacy Cohort Model rows 55-68 builds from disclosed 2025A target (C45=954.2) directly; no calibration factor needed. Value 1.2387 preserved for history (blue input annotation). Prior use: scaled 5 pre-rates in cohort build; cohort build retained as reference only. | O23: RETIRED v36: new engine ties to Drivers!C45 directly via Legacy Cohort Model!D65. Value 1.2387 kept as history.
A24: x | B24: --- ACQUIRED POOL (Wells Fargo, closed 1/1/26) ---
B25: Acquired_pool_cars | C25: 98535 | O25: Deck p.23: ~98,535 acquired via GABX
B26: Acquired_pool_H1_2026_rev | C26: 271.5 | O26: 10-Q Note 7 p.11: GABX total revenue H1 2026 (also = GABX Mini P&L C4)
B27: Acquired_pool_renewal_pct_2027 | C27: 0.17 | O27: Assumption: 17% of acquired fleet expiring in 2027
B28: Acquired_pool_renewal_pct_2028 | C28: 0.17 | O28: Assumption: level
A29: x | B29: --- LPI + RENEWAL SUCCESS ---
B30: LPI_Q1_2026 | C30: 0.223 | O30: Q2 release 5-qtr table
B31: LPI_Q2_2026 | C31: 0.168 | O31: Q2 release: LPI +16.8%
B32: LPI_FY2026 | C32: 0.185 | O32: Assumption: blend Q1 22.3%, Q2 16.8%, H2 mid-cycle
B33: LPI_FY2027 | C33: =CHOOSE(Drivers!$C$736,Drivers!$D$740,Drivers!$E$740,Drivers!$F$740) -> 0.15 | O33: Assumption: decel from Q2 2026 print
B34: LPI_FY2028 | C34: =CHOOSE(Drivers!$C$736,Drivers!$D$741,Drivers!$E$741,Drivers!$F$741) -> 0.1 | O34: Assumption
B35: LPI_FY2029 | C35: =CHOOSE(Drivers!$C$736,Drivers!$D$742,Drivers!$E$742,Drivers!$F$742) -> 0.05 | O35: Assumption: cycle turn
B36: LPI_FY2030 | C36: =CHOOSE(Drivers!$C$736,Drivers!$D$743,Drivers!$E$743,Drivers!$F$743) -> -0.02 | O36: Assumption: cycle low
B37: Renewal_success_FY2026 | C37: =CHOOSE(Drivers!$C$736,Drivers!$D$746,Drivers!$E$746,Drivers!$F$746) -> 0.808 | O37: Assumption: avg Q1 79.1% + Q2 82.6%
B38: Renewal_success_FY2027 | C38: =CHOOSE(Drivers!$C$736,Drivers!$D$747,Drivers!$E$747,Drivers!$F$747) -> 0.85 | O38: Assumption: normalizing
B39: Renewal_phasing_factor | C39: 0.842 | O39: Assumption: mid-year timing convention
B40: Failed_renewal_market_rate | C40: 8100 | O40: Assumption: failed renewals re-lease at market
A41: x | B41: --- SEGMENT REVENUE 2025A ---
...

Sheet Historicals
C2: ="Financial Statement Model - "&Cover!$D$5 -> Financial Statement Model - GATX Corporation
C3: $ mm except per share
C5: Company name | D5: =Cover!$D$5 -> GATX Corporation
C6: Ticker | D6: =Cover!$D$6 -> GATX
C7: Circ break 1=off, 0=on | D7: =Cover!$D$7 -> 1
C8: Latest closing share price | D8: =Cover!$D$8 -> 162.78
C9: Share price date | D9: =Cover!$D$9 -> 46303
C10: Latest fiscal year end | D10: =Cover!$D$10 -> 46022
C11: Shares outstanding (millions) | D11: =Cover!$D$11 -> 35.8
C13: HISTORICALS 2020-2025 — each BS/IS/CFS line from that year's own 10-K
A15: x | C15: INCOME STATEMENT ($M) — FY2022 10-K for 2020-22, FY2025 10-K for 2023-25 | D15: 2020A | E15: 2021A | F15: 2022A | G15: 2023A | H15: 2024A | I15: 2025A
C16: Lease revenue | D16: 1087.5 | E16: 1140.5 | F16: 1154.6 | G16: 1251.4 | H16: 1381.1 | I16: 1486.2 | P16: FY2022 10-K p.60 (2020-22 columns); FY2025 10-K p.60 (2023-25).
C17: Non-dedicated engine revenue | D17: 0 | E17: 0 | F17: 1.5 | G17: 37.6 | H17: 64.6 | I17: 86.7
C18: Marine operating revenue | D18: 15.6 | E18: 19.1 | F18: 18.9 | G18: 6.9 | H18: 0 | I18: 0
C19: Other revenue | D19: 106.1 | E19: 97.8 | F19: 98 | G19: 115 | H19: 139.8 | I19: 167.5
C20: Total Revenues | D20: 1209.2 | E20: 1257.4 | F20: 1273 | G20: 1410.9 | H20: 1585.5 | I20: 1740.4
C21: Maintenance expense | D21: -315.5 | E21: -297.1 | F21: -292.7 | G21: -344.8 | H21: -381.6 | I21: -427.7
C22: Marine operating expense | D22: -19.7 | E22: -17.5 | F22: -14.1 | G22: -6.5 | H22: 0 | I22: 0
C23: Depreciation expense | D23: -330.5 | E23: -364.4 | F23: -357.5 | G23: -376.3 | H23: -402.4 | I23: -431.8
C24: Operating lease expense | D24: -49.3 | E24: -39.2 | F24: -36.1 | G24: -36 | H24: -33.9 | I24: -28.9
C25: Other operating expense | D25: -35.3 | E25: -44 | F25: -37.4 | G25: -46.6 | H25: -57.7 | I25: -65.3
C26: SG&A | D26: -172 | E26: -198.3 | F26: -195 | G26: -212.7 | H26: -236.3 | I26: -252.6
C27: Total Expenses | D27: -922.3 | E27: -960.5 | F27: -932.8 | G27: -1022.9 | H27: -1111.9 | I27: -1206.3
C28: Net gain on asset dispositions | D28: 41.7 | E28: 105.9 | F28: 77.9 | G28: 130.3 | H28: 138.3 | I28: 136.9
... C36: Diluted EPS | D36: 4.28 | E36: 4.02 | F36: 4.36 | G36: 7.12 | H36: 7.78 | I36: 9.12
C39: BALANCE SHEET ($M) — each year from that year's own 10-K | D39: 2020A | E39: 2021A | F39: 2022A | G39: 2023A | H39: 2024A | I39: 2025A
C40: Cash and cash equivalents | D40: 292.2 | E40: 344.3 | F40: 303.7 | G40: 450.7 | H40: 401.6 | I40: 743 | P40: 2020: FY2020 10-K p.59. 2021: FY2021 10-K p.59. 2022: FY2022 10-K p.55. 2023: FY2023 10-K p.56. 2024: FY2024 10-K p.57. 2025: FY2025 10-K p.58.
C41: Restricted cash | D41: 0.4 | E41: 0.2 | F41: 0.3 | G41: 0.1 | H41: 0.2 | I41: 4241.9
C42: Short-term investments | D42: 0 | E42: 0 | F42: 148.5 | G42: 0 | H42: 0 | I42: 0
C43: Receivables (net) | D43: 142.2 | E43: 163.8 | F43: 162 | G43: 218.4 | H43: 199.1 | I43: 207.2
C44: Operating assets and facilities, gross | D44: 10484 | E44: 11163.6 | F44: 11675 | G44: 13081.9 | H44: 14330.6 | I44: 15662.6
C45: Accum depreciation | D45: -3313.3 | E45: -3378.8 | F45: -3424.7 | G45: -3670.7 | H45: -3880.9 | I45: -4251.7
C46: Operating assets and facilities, net | D46: 7170.7 | E46: 7784.8 | F46: 8250.3 | G46: 9411.2 | H46: 10449.7 | I46: 11410.9
C47: Right-of-use assets | D47: 335.9 | E47: 270.7 | F47: 243.5 | G47: 212 | H47: 165.4 | I47: 137.4
C48: Finance leases (as lessee) | D48: 37.5 | E48: 1.5 | F48: 0 | G48: 0 | H48: 0 | I48: 0
C49: Investments in Affiliated Companies | D49: 584.7 | E49: 588.4 | F49: 575.1 | G49: 627 | H49: 663.3 | I49: 732.3
C50: Goodwill | D50: 143.7 | E50: 123 | F50: 117.2 | G50: 120 | H50: 114.1 | I50: 126.3
C51: Other Assets | D51: 230.3 | E51: 265 | F51: 271.4 | G51: 286.6 | H51: 303.1 | I51: 400.5
C52: Total Assets | D52: 8937.6 | E52: 9541.7 | F52: 10072 | G52: 11326 | H52: 12296.5 | I52: 17999.5
... C70: Total Liabilities and Equity | D70: 8937.6 | E70: 9541.7 | F70: 10072 | G70: 11326 | H70: 12296.5 | I70: 17999.5
...

Sheet 3 Statement Forecast
C2: ="Financial Statement Model - "&Cover!$D$5 -> Financial Statement Model - GATX Corporation
C3: $ mm except per share
C5: Company name | D5: =Cover!$D$5 -> GATX Corporation
C6: Ticker | D6: =Cover!$D$6 -> GATX
C7: Circ break 1=off, 0=on | D7: =Cover!$D$7 -> 1
C8: Latest closing share price | D8: =Cover!$D$8 -> 162.78
C9: Share price date | D9: =Cover!$D$9 -> 46303
C10: Latest fiscal year end | D10: =Cover!$D$10 -> 46022
C11: Shares outstanding (millions) | D11: =Cover!$D$11 -> 35.8
C13: GATX 3-STATEMENT FORECAST — 2025A from filings, 2026-27E from model. Revolver-plug.
D15: 2025A | E15: 2026E | F15: 2027E | G15: 2028E | H15: 2029E | I15: 2030E | J15: 2031E | K15: 2032E | L15: 2033E | M15: 2034E | N15: 2035E
A16: x | C16: INCOME STATEMENT ($M)
C17: Total revenue | D17: ='Segment P&L'!D36 -> 1740.4 | E17: ='Segment P&L'!E36 -> 2385.4547 | F17: ='Segment P&L'!F36 -> 2471.4791 | G17: ='Segment P&L'!G36 -> 2553.7116 | H17: ='Segment P&L'!H36 -> 2622.8806 | I17: ='Segment P&L'!I36 -> 2673.4938 | J17: ='Segment P&L'!J36 -> 2715.5694 | K17: ='Segment P&L'!K36 -> 2762.9249 | ... N17: ='Segment P&L'!N36 -> 2913.282
C18: Maintenance | D18: -427.7 | E18: =-E17*Drivers!$C$128 -> -599.54072 | F18: =-F17*Drivers!$C$128 -> -621.16139 | G18: =-G17*Drivers!$C$128 -> -641.82905 | H18: =-H17*Drivers!$C$128 -> -659.21342 | I18: =-I17*Drivers!$C$128 -> -671.93412 | J18: =-J17*Drivers!$C$128 -> -682.50906 | K18: =-K17*Drivers!$C$128 -> -694.41101 | L18: =-L17*Drivers!$C$128 -> -706.6518 | ... N18: =-N17*Drivers!$C$128 -> -732.20054
C19: Depreciation | D19: -431.8 | E19: =-Drivers!$C$124 -> -671.4 | F19: =-Drivers!$C$125 -> -720 | G19: =-Drivers!$C$303 -> -720 | H19: =-Drivers!$C$304 -> -720 | I19: =-Drivers!$C$305 -> -720 | J19: =-Drivers!$C$558 -> -720 | K19: =-Drivers!$C$559 -> -732.8353 | L19: =-Drivers!$C$560 -> -743.92318 | M19: =-Drivers!$C$561 -> -755.12194 | N19: =-Drivers!$C$562 -> -766.43269
C20: Operating lease expense | D20: -28.9 | E20: =-Drivers!$C$129 -> -29.6 | F20: =-Drivers!$C$129 -> -29.6 | G20: =-Drivers!$C$129 -> -29.6 | H20: =-Drivers!$C$129 -> -29.6 | I20: =-Drivers!$C$129 -> -29.6 | J20: =-Drivers!$C$129 -> -29.6 | K20: =-Drivers!$C$129 -> -29.6 | L20: =-Drivers!$C$129 -> -29.6 | ... N20: =-Drivers!$C$129 -> -29.6
C21: Other operating expense | D21: -65.3 | E21: =-E17*Drivers!$C$130 -> -95.418186 | F21: =-F17*Drivers!$C$130 -> -98.859162 | G21: =-G17*Drivers!$C$130 -> -102.14846 | H21: =-H17*Drivers!$C$130 -> -104.91523 | I21: =-I17*Drivers!$C$130 -> -106.93975 | J21: =-J17*Drivers!$C$130 -> -108.62278 | K21: =-K17*Drivers!$C$130 -> -110.517 | L21: =-L17*Drivers!$C$130 -> -112.46514 | ... N21: =-N17*Drivers!$C$130 -> -116.53128
C22: SG&A | D22: -252.6 | E22: =-E17*Drivers!$C$127 -> -288.64001 | F22: =-F17*Drivers!$C$127 -> -299.04897 | G22: =-G17*Drivers!$C$127 -> -308.9991 | H22: =-H17*Drivers!$C$127 -> -317.36856 | I22: =-I17*Drivers!$C$127 -> -323.49274 | J22: =-J17*Drivers!$C$127 -> -328.58389 | K22: =-K17*Drivers!$C$127 -> -334.31391 | L22: =-L17*Drivers!$C$127 -> -340.20706 | ... N22: =-N17*Drivers!$C$127 -> -352.50712
C23: Net gain on asset dispositions (legacy engine + GABX row 10) | D23: 136.9 | E23: ='Disposition Engine'!D44+'GABX Mini P&L'!G22 -> 210.5 | F23: ='Disposition Engine'!E44+'GABX Mini P&L'!H22 -> 210.5 | G23: ='Disposition Engine'!F44+'GABX Mini P&L'!I22 -> 210.49926 | H23: ='Disposition Engine'!G44+'GABX Mini P&L'!J22 -> 210.49926 | I23: ='Disposition Engine'!H44+'GABX Mini P&L'!K22 -> 210.49926 | J23: ='Disposition Engine'!I44+'GABX Mini P&L'!L22 -> 217.86674 | K23: ='Disposition Engine'!J44+'GABX Mini P&L'!M22 -> 220.40246 | L23: ='Disposition Engine'!K44+'GABX Mini P&L'!N22 -> 223.02694 | ... N23: ='Disposition Engine'!M44+'GABX Mini P&L'!P22 -> 228.55467
C24: Interest expense, net (from Debt sheet) | D24: ='Debt & Interest'!D31 -> -391.5 | E24: ='Debt & Interest'!E31 -> -588.82599 | F24: ='Debt & Interest'!F31 -> -615.70826 | G24: ='Debt & Interest'!G31 -> -642.39824 | H24: ='Debt & Interest'!H31 -> -669.29324 | I24: ='Debt & Interest'!I31 -> -715.76368 | J24: ='Debt & Interest'!J31 -> -727.51591 | K24: ='Debt & Interest'!K31 -> -739.77159 | ... N24: ='Debt & Interest'!N31 -> -767.65406
C25: Other income (expense) | D25: -0.4 | E25: =Drivers!$C$142 -> 10.4 | F25: =Drivers!$C$143 -> 10 | G25: =Drivers!$C$312 -> 10 | H25: =Drivers!$C$313 -> 10 | I25: =Drivers!$C$314 -> 10 | J25: =Drivers!$C$548 -> 10 | K25: =Drivers!$C$549 -> 10 | L25: =Drivers!$C$550 -> 10 | M25: =Drivers!$C$551 -> 10 | N25: =Drivers!$C$552 -> 10
C26: Pretax income (pre-affiliates) | D26: =D17+D18+D19+D20+D21+D22+D23+D24+D25 -> 279.1 | E26: =E17+E18+E19+E20+E21+E22+E23+E24+E25 -> 332.92975 | F26: =F17+F18+F19+F20+F21+F22+F23+F24+F25 -> 307.60128 | G26: =G17+G18+G19+G20+G21+G22+G23+G24+G25 -> 329.23602 | H26: =H17+H18+H19+H20+H21+H22+H23+H24+H25 -> 342.98945 | I26: =I17+I18+I19+I20+I21+I22+I23+I24+I25 -> 326.26273 | J26: =J17+J18+J19+J20+J21+J22+J23+J24+J25 -> 346.60448 | K26: =K17+K18+K19+K20+K21+K22+K23+K24+K25 -> 351.87855 | ... N26: =N17+N18+N19+N20+N21+N22+N23+N24+N25 -> 386.91098
C27: Income taxes | D27: -63.1 | E27: =-E26*Drivers!$C$75 -> -87.560524 | F27: =-F26*Drivers!$C$76 -> -73.824307 | G27: =-G26*Drivers!$C$273 -> -79.016644 | H27: =-H26*Drivers!$C$274 -> -82.317467 | I27: =-I26*Drivers!$C$275 -> -78.303055 | J27: =-J26*Drivers!$C$498 -> -83.185075 | K27: =-K26*Drivers!$C$499 -> -84.450851 | L27: =-L26*Drivers!$C$500 -> -86.980988 | M27: =-M26*Drivers!$C$501 -> -89.782969 | N27: =-N26*Drivers!$C$502 -> -92.858635
C28: Share of affiliates (RRPF), net of tax | D28: 117.3 | E28: =Drivers!$C$113 -> 140 | F28: =Drivers!$C$114 -> 150 | G28: =Drivers!$C$294 -> 150 | H28: =Drivers!$C$295 -> 150 | I28: =Drivers!$C$296 -> 150 | J28: =Drivers!$C$528 -> 150 | K28: =Drivers!$C$529 -> 150 | L28: =Drivers!$C$530 -> 150 | M28: =Drivers!$C$531 -> 150 | N28: =Drivers!$C$532 -> 150
C29: Net Income (consolidated) | D29: =D26+D27+D28 -> 333.3 | E29: =E26+E27+E28 -> 385.36922 | F29: =F26+F27+F28 -> 383.77697 | G29: =G26+G27+G28 -> 400.21937 | H29: =H26+H27+H28 -> 410.67198 | I29: =I26+I27+I28 -> 397.95967 | J29: =J26+J27+J28 -> 413.4194 | K29: =K26+K27+K28 -> 417.42769 | ... N29: =N26+N27+N28 -> 444.05234
C30: Less: NCI (from GABX Mini P&L) | D30: 0 | E30: =-'GABX Mini P&L'!G27 -> -17.01504 | F30: =-'GABX Mini P&L'!H27 -> -25.309791 | G30: =-'GABX Mini P&L'!I27 -> -29.719233 | H30: =-'GABX Mini P&L'!J27 -> -29.035726 | I30: =-'GABX Mini P&L'!K27 -> -23.440796 | J30: =-'GABX Mini P&L'!L27 -> -22.700665 | K30: =-'GABX Mini P&L'!M27 -> -20.445024 | L30: =-'GABX Mini P&L'!N27 -> -16.629065 | ... N30: =-'GABX Mini P&L'!P27 -> -4.1300084
C31: NI attributable to GATX | D31: =D29+D30 -> 333.3 | E31: =E29+E30 -> 368.35418 | F31: =F29+F30 -> 358.46718 | G31: =G29+G30 -> 370.50014 | H31: =H29+H30 -> 381.63625 | I31: =I29+I30 -> 374.51888 | J31: =J29+J30 -> 390.71874 | K31: =K29+K30 -> 396.98267 | ... N31: =N29+N30 -> 439.92234
C32: Diluted shares (M) | D32: 35.9 | E32: =Drivers!$C$77 -> 35.8 | F32: =Drivers!$C$78 -> 35.22652 | G32: =Drivers!$C$276 -> 34.672433 | H32: =Drivers!$C$277 -> 34.137083 | I32: =Drivers!$C$278 -> 33.619837 | J32: =Drivers!$C$503 -> 33.098466 | K32: =Drivers!$C$504 -> 32.586649 | L32: =Drivers!$C$505 -> 32.077407 | M32: =Drivers!$C$506 -> 31.56818 | N32: =Drivers!$C$507 -> 31.056618
C33: Diluted EPS | D33: =D31/D32 -> 9.2841226 | E33: =E31/E32 -> 10.289223 | F33: =F31/F32 -> 10.17606 | G33: =G31/G32 -> 10.685727 | H33: =H31/H32 -> 11.179521 | I33: =I31/I32 -> 11.139818 | J33: =J31/J32 -> 11.804739 | K33: =K31/K32 -> 12.182372 | ... N33: =N31/N32 -> 14.165172
A35: x | C35: BALANCE SHEET ($M) — 2025A from FY2025 10-K p.58
C36: Cash and cash equivalents | D36: 743 | E36: 747.1 | F36: 747.1 | G36: 747.1 | H36: 747.1 | I36: 747.1 | J36: =I36 -> 747.1 | K36: =J36 -> 747.1 | L36: =K36 -> 747.1 | M36: =L36 -> 747.1 | N36: =M36 -> 747.1
C37: Restricted cash | D37: 4241.9 | E37: 0.1 | F37: 0.1 | G37: 0.1 | H37: 0.1 | I37: 0.1 | J37: 0.1 | K37: 0.1 | L37: 0.1 | M37: 0.1 | N37: 0.1
C38: Receivables (net) | D38: 207.2 | E38: =D38*(E17/D17) -> 283.99575 | F38: =E38*(F17/E17) -> 294.23722 | G38: =F38*(G17/F17) -> 304.02726 | H38: =G38*(H17/G17) -> 312.26205 | I38: =H38*(I17/H17) -> 318.2877 | J38: =I38*(J17/I17) -> 323.29693 | K38: =J38*(K17/J17) -> 328.93475 | L38: =K38*(L17/K17) -> 334.73308 | ... N38: =M38*(N17/M17) -> 346.83523
C39: PP&E net (BOP + WF + capex − depr − dispo book) | D39: 11410.9 | E39: =D39+Drivers!$C$123+Drivers!$C$121+E19-Drivers!$C$86 -> 15830.5 | F39: =E39+Drivers!$C$122+F19-Drivers!$C$87 -> 16360.5 | G39: =F39+Drivers!$C$300+G19-Drivers!$C$288 -> 16890.5 | H39: =G39+Drivers!$C$301+H19-Drivers!$C$289 -> 17420.5 | I39: =H39+Drivers!$C$302+I19-Drivers!$C$290 -> 17950.5 | J39: =I39+Drivers!$C$563+J19-Drivers!$C$553 -> 18270.5 | K39: =J39+Drivers!$C$564+K19-Drivers!$C$554 -> 18546.935 | L39: =K39+Drivers!$C$565+L19-Drivers!$C$555 -> 18826.134 | M39: =L39+Drivers!$C$566+M19-Drivers!$C$556 -> 19108.125 | N39: =M39+Drivers!$C$567+N19-Drivers!$C$557 -> 19392.936
C40: Right-of-use assets (net) | D40: 137.4 | E40: 127.5 | F40: 120 | G40: 112.5 | H40: 105 | I40: 97.5 | J40: 90 | K40: 82.5 | L40: 75 | M40: 67.5 | N40: 60
C41: Investments in Affiliated Companies | D41: 732.3 | E41: =D41+Drivers!$C$113-Drivers!$C$115 -> 732.3 | F41: =E41+Drivers!$C$114-Drivers!$C$116 -> 752.3 | G41: =F41+Drivers!$C$294-Drivers!$C$297 -> 772.3 | H41: =G41+Drivers!$C$295-Drivers!$C$298 -> 792.3 | I41: =H41+Drivers!$C$296-Drivers!$C$299 -> 812.3 | J41: =I41+Drivers!$C$528-Drivers!$C$533 -> 832.3 | K41: =J41+Drivers!$C$529-Drivers!$C$534 -> 852.3 | L41: =K41+Drivers!$C$530-Drivers!$C$535 -> 872.3 | M41: =L41+Drivers!$C$531-Drivers!$C$536 -> 892.3 | N41: =M41+Drivers!$C$532-Drivers!$C$537 -> 912.3
C42: Goodwill | D42: 126.3 | E42: 126.3 | F42: 126.3 | G42: 126.3 | H42: 126.3 | I42: 126.3 | J42: 126.3 | K42: 126.3 | L42: 126.3 | M42: 126.3 | N42: 126.3
C43: Other Assets | D43: 400.5 | E43: =D43 -> 400.5 | F43: =E43 -> 400.5 | G43: =F43 -> 400.5 | H43: =G43 -> 400.5 | I43: =H43 -> 400.5 | J43: =I43 -> 400.5 | K43: =J43 -> 400.5 | L43: =K43 -> 400.5 | ... N43: =M43 -> 400.5
C44: Total Assets | D44: =D36+D37+D38+D39+D40+D41+D42+D43 -> 17999.5 | E44: =E36+E37+E38+E39+E40+E41+E42+E43 -> 18248.296 | F44: =F36+F37+F38+F39+F40+F41+F42+F43 -> 18801.037 | G44: =G36+G37+G38+G39+G40+G41+G42+G43 -> 19353.327 | H44: =H36+H37+H38+H39+H40+H41+H42+H43 -> 19904.062 | I44: =I36+I37+I38+I39+I40+I41+I42+I43 -> 20452.588 | J44: =J36+J37+J38+J39+J40+J41+J42+J43 -> 20790.097 | K44: =K36+K37+K38+K39+K40+K41+K42+K43 -> 21084.669 | ... N44: =N36+N37+N38+N39+N40+N41+N42+N43 -> 21986.071
C46: Accounts payable and accrued expenses | D46: 318.4 | E46: =D46*(E17/D17) -> 436.41046 | F46: =E46*(F17/E17) -> 452.14832 | G46: =F46*(G17/F17) -> 467.19247 | H46: =G46*(H17/G17) -> 479.8467 | I46: =H46*(I17/H17) -> 489.10619 | J46: =I46*(J17/I17) -> 496.80377 | K46: =J46*(K17/J17) -> 505.4673 | L46: =K46*(L17/K17) -> 514.37747 | ... N46: =M46*(N17/M17) -> 532.9746
...

Sheet Debt & Interest
C2: ="Financial Statement Model - "&Cover!$D$5 -> Financial Statement Model - GATX Corporation
C3: $ mm except per share
C5: Company name | D5: =Cover!$D$5 -> GATX Corporation
C6: Ticker | D6: =Cover!$D$6 -> GATX
C7: Circ break 1=off, 0=on | D7: =Cover!$D$7 -> 1
C8: Latest closing share price | D8: =Cover!$D$8 -> 162.78
C9: Share price date | D9: =Cover!$D$9 -> 46303
C10: Latest fiscal year end | D10: =Cover!$D$10 -> 46022
C11: Shares outstanding (millions) | D11: =Cover!$D$11 -> 35.8
C13: DEBT & INTEREST — Q2 10-Q p.42 ladder rolled forward
C15: Debt roll: BOP − maturities + refinancing at Drivers!New_issue_rate + net new issuance (from cash plug).
C16: Interest expense = (BOP + EOP)/2 × Fixed_cost_of_debt. FY2026 gate: within 3% of $588.0M (H1 $294.0M × 2).
A18: x | C18: MATURITY LADDER (10-Q p.42) | D18: 2026 rem | E18: 2027 | F18: 2028 | G18: 2029 | H18: 2030 | I18: Thereafter
C19: Recourse debt maturities | D19: =Drivers!$C$90 -> 633.8 | E19: =Drivers!$C$91 -> 848.1 | F19: =Drivers!$C$92 -> 819.4 | G19: =Drivers!$C$93 -> 850 | H19: =Drivers!$C$94 -> 2576.4 | I19: =Drivers!$C$95 -> 6615.2
C20: Interest scheduled (10-Q p.42) | D20: =Drivers!$C$96 -> 294.2 | E20: =Drivers!$C$97 -> 542.1 | F20: =Drivers!$C$98 -> 511.1
C22: DEBT ROLL ($M) — BOP − maturities + refi + net new (from cash plug) | D22: 2025A | E22: 2026E | F22: 2027E | G22: 2028E | H22: 2029E | I22: 2030E | J22: 2031E | K22: 2032E | L22: 2033E | M22: 2034E | N22: 2035E
C23: Total debt BOP | D23: =Drivers!$C$101 -> 12533.9 | E23: =Drivers!$C$101 -> 12533.9 | F23: =E27 -> 12516.956 | G23: =F27 -> 13017.969 | H23: =G27 -> 13493.695 | I23: =H27 -> 13952.432 | J23: =I27 -> 14418.254 | K23: =J27 -> 14661.143 | L23: =K27 -> 14851.717 | M23: =L27 -> 15035.772 | N23: =M27 -> 15213.731
C24: Less: maturities | D24: 0 | E24: =-Drivers!$C$90 -> -633.8 | F24: =-Drivers!$C$91 -> -848.1 | G24: =-Drivers!$C$92 -> -819.4 | H24: =-Drivers!$C$93 -> -850 | I24: =-Drivers!$C$94 -> -2576.4 | J24: 0 | K24: 0 | L24: 0 | M24: 0 | N24: 0
C25: Plus: refinancing at New_issue_rate | D25: 0 | E25: =Drivers!$C$90 -> 633.8 | F25: =Drivers!$C$91 -> 848.1 | G25: =Drivers!$C$92 -> 819.4 | H25: =Drivers!$C$93 -> 850 | I25: =Drivers!$C$94 -> 2576.4 | J25: 0 | K25: 0 | L25: 0 | M25: 0 | N25: 0
C26: Net new issuance (cash plug from CFS) | D26: 0 | E26: ='3 Statement Forecast'!E82 -> -16.944005 | F26: ='3 Statement Forecast'!F82 -> 501.01258 | G26: ='3 Statement Forecast'!G82 -> 475.72665 | H26: ='3 Statement Forecast'!H82 -> 458.73662 | I26: ='3 Statement Forecast'!I82 -> 465.82236 | J26: ='3 Statement Forecast'!J82 -> 242.88898 | K26: ='3 Statement Forecast'!K82 -> 190.57389 | L26: ='3 Statement Forecast'!L82 -> 184.05498 | ... N26: ='3 Statement Forecast'!N82 -> 172.30919
C27: Total debt EOP | D27: =D23+D24+D25+D26 -> 12533.9 | E27: =E23+E24+E25+E26 -> 12516.956 | F27: =F23+F24+F25+F26 -> 13017.969 | G27: =G23+G24+G25+G26 -> 13493.695 | H27: =H23+H24+H25+H26 -> 13952.432 | I27: =I23+I24+I25+I26 -> 14418.254 | J27: =J23+J24+J25+J26 -> 14661.143 | K27: =K23+K24+K25+K26 -> 14851.717 | ... N27: =N23+N24+N25+N26 -> 15386.04
C28: Average debt balance | D28: =D27 -> 12533.9 | E28: =(E23+E27)/2 -> 12525.428 | F28: =(F23+F27)/2 -> 12767.462 | G28: =(G23+G27)/2 -> 13255.832 | H28: =(H23+H27)/2 -> 13723.064 | I28: =(I23+I27)/2 -> 14185.343 | J28: =(J23+J27)/2 -> 14539.699 | K28: =(K23+K27)/2 -> 14756.43 | L28: =(L23+L27)/2 -> 14943.745 | ... N28: =(N23+N27)/2 -> 15299.886
C29: Non-GABX debt (fixed rate) | D29: =Drivers!$C$168 -> 9616.5 | E29: =Drivers!$C$168 -> 9616.5 | F29: =Drivers!$C$168+Drivers!$C$88 -> 10016.5 | G29: =F29+Drivers!$C$291 -> 10416.5 | H29: =G29+Drivers!$C$292 -> 10816.5 | I29: =H29+Drivers!$C$293 -> 11216.5 | J29: =J27-J30 -> 11800.943 | K29: =K27-K30 -> 11991.517 | L29: =L27-L30 -> 12175.572 | M29: =M27-M30 -> 12353.531 | N29: =N27-N30 -> 12525.84
C30: GABX debt (floating, mostly hedged) | D30: =Drivers!$C$106 -> 2942.9 | E30: =Drivers!$C$107 -> 2860.2 | F30: =Drivers!$C$107 -> 2860.2 | G30: =Drivers!$C$107 -> 2860.2 | H30: =Drivers!$C$107 -> 2860.2 | I30: =Drivers!$C$107 -> 2860.2 | J30: =I30 -> 2860.2 | K30: =J30 -> 2860.2 | L30: =K30 -> 2860.2 | M30: =L30 -> 2860.2 | N30: =M30 -> 2860.2
C31: Interest expense (Non-GABX×fixed + GABX×float; net float hedged flat) | D31: -391.5 | E31: =-(Drivers!$C$168*Drivers!$C$170+E30*Drivers!$C$108) -> -588.82599 | F31: =-((Drivers!$C$168-Drivers!$C$91)*Drivers!$C$170+Drivers!$C$91*Drivers!$C$102+Drivers!$C$88*Drivers!$C$102+F30*Drivers!$C$108) -> -615.70826 | G31: =-((Drivers!$C$168-Drivers!$C$91-Drivers!$C$92)*Drivers!$C$170+(Drivers!$C$91+Drivers!$C$92)*Drivers!$C$102+(Drivers!$C$88+Drivers!$C$291)*Drivers!$C$102+G30*Drivers!$C$108) -> -642.39824 | H31: =-((Drivers!$C$168-Drivers!$C$91-Drivers!$C$92-Drivers!$C$93)*Drivers!$C$170+(Drivers!$C$91+Drivers!$C$92+Drivers!$C$93)*Drivers!$C$102+(Drivers!$C$88+Drivers!$C$291+Drivers!$C$292)*Drivers!$C$102+H30*Drivers!$C$108) -> -669.29324 | I31: =-((Drivers!$C$168-Drivers!$C$91-Drivers!$C$92-Drivers!$C$93-Drivers!$C$94)*Drivers!$C$170+(Drivers!$C$91+Drivers!$C$92+Drivers!$C$93+Drivers!$C$94)*Drivers!$C$102+(Drivers!$C$88+Drivers!$C$291+Drivers!$C$292+Drivers!$C$293)*Drivers!$C$102+I30*Drivers!$C$102) -> -715.76368 | J31: =$I$31/$I$28*J23 -> -727.51591 | K31: =$I$31/$I$28*K23 -> -739.77159 | L31: =$I$31/$I$28*L23 -> -749.38756 | M31: =$I$31/$I$28*M23 -> -758.67461 | N31: =$I$31/$I$28*N23 -> -767.65406 | P31: GATE: 2026E within 3% of -$588.0M (H1 $294.0M × 2)
C32: Kill test delta 2027: 6.00% on 2027 refi + growth only | E32: =-E29*(Drivers!$C$105-Drivers!$C$104) -> -131.74605 | F32: =-(Drivers!$C$105-Drivers!$C$102)*(Drivers!$C$91+Drivers!$C$88) -> -8.7367 | G32: =-(Drivers!$C$105-Drivers!$C$102)*(Drivers!$C$91+Drivers!$C$92+Drivers!$C$88+Drivers!$C$291) -> -17.2725 | H32: =-(Drivers!$C$105-Drivers!$C$102)*(Drivers!$C$91+Drivers!$C$92+Drivers!$C$93+Drivers!$C$88+Drivers!$C$291+Drivers!$C$292) -> -26.0225 | I32: =-(Drivers!$C$105-Drivers!$C$102)*(Drivers!$C$91+Drivers!$C$92+Drivers!$C$93+Drivers!$C$94+Drivers!$C$88+Drivers!$C$291+Drivers!$C$292+Drivers!$C$293) -> -46.8573 | P32: Sensitivity: substitute Kill (6.00%) for New_issue_rate (5.30%) moves only the refi + growth tranche, not the full debt stack.
A34: x | C34: FIXED / FLOATING BREAKOUT (10-Q p.42) | D34: Q2 2026
C35: Fixed debt | D35: =Drivers!$C$168 -> 9616.5
C36: Floating debt (gross) | D36: =Drivers!$C$169 -> 2672.8
C37: Less: cash-flow hedges (SOFR fixed) | D37: =-Drivers!$C$173 -> -1754.4
C38: Net floating exposure | D38: =D36+D37 -> 918.4 | P38: [note] refers to Drivers!Net_floating_exposure (audit link)
C39: Fair-value hedges (float on fixed) | D39: =Drivers!$C$174 -> 50
C40: Weighted fixed coupon | D40: =Drivers!$C$170 -> 0.0463
C41: Floating all-in rate (SOFR + spread) | D41: =Drivers!$C$171 -> 0.0525
C42: Memo: net-float interest sensitivity (Δ100bp) | D42: =D38*0.01 -> 9.184 | P42: $M / 100bp move in SOFR on net_floating exposure (post-hedge).
A44: x | C44: 2030 REFI EFFECT BREAKOUT (v9 Section 3, 2026-09-25)
C45: FY2030 interest ex-2030-refi (i.e., pre-2030 refi state) | I45: =-((Drivers!$C$168-Drivers!$C$91-Drivers!$C$92-Drivers!$C$93)*Drivers!$C$170+(Drivers!$C$91+Drivers!$C$92+Drivers!$C$93)*Drivers!$C$102+(Drivers!$C$88+Drivers!$C$291+Drivers!$C$292+Drivers!$C$293)*Drivers!$C$102+I30*Drivers!$C$108) -> -690.49324
C46: 2030 refi effect — $2,576M maturity × (New_issue_rate − old coupon) | I46: =-Drivers!$C$94*(Drivers!$C$102-Drivers!$C$170) -> -17.26188
C47: 2030 refi effect — GABX term loan × (New_issue_rate − GABX_rate) | I47: =-I30*(Drivers!$C$102-Drivers!$C$108) -> -8.00856
C48: Total 2030 interest = ex-refi + $2,576M refi + GABX refi (check = row 19 col G) | I48: =I45+I46+I47 -> -715.76368
...

Sheet Legacy Cohort Model
C2: ="Financial Statement Model - "&Cover!$D$5 -> Financial Statement Model - GATX Corporation
C3: $ mm except per share
C5: Company name | D5: =Cover!$D$5 -> GATX Corporation
C6: Ticker | D6: =Cover!$D$6 -> GATX
C7: Circ break 1=off, 0=on | D7: =Cover!$D$7 -> 1
C8: Latest closing share price | D8: =Cover!$D$8 -> 162.78
C9: Share price date | D9: =Cover!$D$9 -> 46303
C10: Latest fiscal year end | D10: =Cover!$D$10 -> 46022
C11: Shares outstanding (millions) | D11: =Cover!$D$11 -> 35.8
C13: v36 LEGACY FLEET MODEL — disclosed-expiration-driven renewal engine (rows 55-68)
C15: v36: engine builds forward from 2025A anchor (Drivers!C45 = 954.2) using disclosed renewal counts × success × expiring-rate × LPI; renewals spread evenly → half year t, half year t+1.
C16: Target: 2025A cohort revenue = Rail NA lease $1,049.1M − boxcars $58.5M − locos $36.4M = $954.2M (10-K p.31 railcars line).
C17: v36 2026-10-07: v34/v35 lumpy single-term-per-year timing REVERTED. Rows 20-42 (5-vintage cohort build) retained as REFERENCE ONLY — do not feed D43 anymore.
C18: v36: rows 21-26 (cohort cars) still feed 3SF!I111:N111 fleet count; rows 29-33 (cohort rates) kept as display; rows 37-42 (cohort rev) now display-only, not summed into D43.
A20: x | C20: COHORT CARS (reference only v36; still feeds 3SF fleet count row 111) — 2025A → | D20: 2025A | E20: 2026E | F20: 2027E | G20: 2028E | H20: 2029E | I20: 2030E | J20: 2031E | K20: 2032E | L20: 2033E | M20: 2034E | N20: 2035E
C21: Cohort 2021 cars | D21: =Drivers!$C$11 -> 20000 | E21: =Drivers!$C$11 -> 20000 | F21: =Drivers!$C$11 -> 20000 | G21: =Drivers!$C$11 -> 20000 | H21: =Drivers!$C$11 -> 20000 | I21: =Drivers!$C$11 -> 20000 | J21: =I21*(1+Drivers!$C$705) -> 20200 | K21: =J21*(1+Drivers!$C$705) -> 20402 | L21: =K21*(1+Drivers!$C$705) -> 20606.02 | M21: =L21*(1+Drivers!$C$705) -> 20812.08 | N21: =M21*(1+Drivers!$C$705) -> 21020.201
C22: Cohort 2022 cars | D22: =Drivers!$C$12 -> 18500 | E22: =Drivers!$C$12 -> 18500 | F22: =Drivers!$C$12 -> 18500 | G22: =Drivers!$C$12 -> 18500 | H22: =Drivers!$C$12 -> 18500 | I22: =Drivers!$C$12 -> 18500 | J22: =I22*(1+Drivers!$C$705) -> 18685 | K22: =J22*(1+Drivers!$C$705) -> 18871.85 | L22: =K22*(1+Drivers!$C$705) -> 19060.569 | M22: =L22*(1+Drivers!$C$705) -> 19251.174 | N22: =M22*(1+Drivers!$C$705) -> 19443.686
C23: Cohort 2023 cars | D23: =Drivers!$C$13 -> 18700 | E23: =Drivers!$C$13 -> 18700 | F23: =Drivers!$C$13 -> 18700 | G23: =Drivers!$C$13 -> 18700 | H23: =Drivers!$C$13 -> 18700 | I23: =Drivers!$C$13 -> 18700 | J23: =I23*(1+Drivers!$C$705) -> 18887 | K23: =J23*(1+Drivers!$C$705) -> 19075.87 | L23: =K23*(1+Drivers!$C$705) -> 19266.629 | M23: =L23*(1+Drivers!$C$705) -> 19459.295 | N23: =M23*(1+Drivers!$C$705) -> 19653.888
C24: Cohort 2024 cars | D24: =Drivers!$C$14 -> 19400 | E24: =Drivers!$C$14 -> 19400 | F24: =Drivers!$C$14 -> 19400 | G24: =Drivers!$C$14 -> 19400 | H24: =Drivers!$C$14 -> 19400 | I24: =Drivers!$C$14 -> 19400 | J24: =I24*(1+Drivers!$C$705) -> 19594 | K24: =J24*(1+Drivers!$C$705) -> 19789.94 | L24: =K24*(1+Drivers!$C$705) -> 19987.839 | M24: =L24*(1+Drivers!$C$705) -> 20187.718 | N24: =M24*(1+Drivers!$C$705) -> 20389.595
C25: Cohort 2025 cars | D25: =Drivers!$C$15 -> 21500 | E25: =Drivers!$C$15 -> 21500 | F25: =Drivers!$C$15 -> 21500 | G25: =Drivers!$C$15 -> 21500 | H25: =Drivers!$C$15 -> 21500 | I25: =Drivers!$C$15 -> 21500 | J25: =I25*(1+Drivers!$C$705) -> 21715 | K25: =J25*(1+Drivers!$C$705) -> 21932.15 | L25: =K25*(1+Drivers!$C$705) -> 22151.471 | M25: =L25*(1+Drivers!$C$705) -> 22372.986 | N25: =M25*(1+Drivers!$C$705) -> 22596.716
C26: Legacy base fleet cars | D26: =Drivers!$C$16 -> 2493 | E26: =Drivers!$C$16 -> 2493 | F26: =Drivers!$C$16 -> 2493 | G26: =Drivers!$C$16 -> 2493 | H26: =Drivers!$C$16 -> 2493 | I26: =Drivers!$C$16 -> 2493 | J26: =I26*(1+Drivers!$C$705) -> 2517.93 | K26: =J26*(1+Drivers!$C$705) -> 2543.1093 | L26: =K26*(1+Drivers!$C$705) -> 2568.5404 | M26: =L26*(1+Drivers!$C$705) -> 2594.2258 | N26: =M26*(1+Drivers!$C$705) -> 2620.1681
C28: RATES ($/car/yr) — factor × pre-rate for the 5 cohorts; base held flat | D28: 2025A | E28: 2026E | F28: 2027E | G28: 2028E | H28: 2029E | I28: 2030E | J28: 2031E | K28: 2032E | L28: 2033E | M28: 2034E | N28: 2035E
C29: Cohort 2021 rate | D29: =(1-Drivers!$D$810)*(Drivers!$C$23*Drivers!$C$17) + (Drivers!$D$810-Drivers!$D$816)*(Drivers!$C$23*Drivers!$C$17)*(1+Drivers!$C$824) + Drivers!$D$816*(Drivers!$C$23*Drivers!$C$17)*(1+Drivers!$C$824)*(1+Drivers!$D$824) -> 9981.4446 | E29: =(1-Drivers!$E$810)*(Drivers!$C$23*Drivers!$C$17) + (Drivers!$E$810-Drivers!$E$816)*(Drivers!$C$23*Drivers!$C$17)*(1+Drivers!$C$824) + Drivers!$E$816*(Drivers!$C$23*Drivers!$C$17)*(1+Drivers!$C$824)*(1+Drivers!$D$824) -> 9981.4446 | F29: =(1-Drivers!$F$810)*(Drivers!$C$23*Drivers!$C$17) + (Drivers!$F$810-Drivers!$F$816)*(Drivers!$C$23*Drivers!$C$17)*(1+Drivers!$C$824) + Drivers!$F$816*(Drivers!$C$23*Drivers!$C$17)*(1+Drivers!$C$824)*(1+Drivers!$D$824) -> 9981.4446 | G29: =(1-Drivers!$G$810)*(Drivers!$C$23*Drivers!$C$17) + (Drivers!$G$810-Drivers!$G$816)*(Drivers!$C$23*Drivers!$C$17)*(1+Drivers!$C$824) + Drivers!$G$816*(Drivers!$C$23*Drivers!$C$17)*(1+Drivers!$C$824)*(1+Drivers!$D$824) -> 9981.4446 | H29: =(1-Drivers!$H$810)*(Drivers!$C$23*Drivers!$C$17) + (Drivers!$H$810-Drivers!$H$816)*(Drivers!$C$23*Drivers!$C$17)*(1+Drivers!$C$824) + Drivers!$H$816*(Drivers!$C$23*Drivers!$C$17)*(1+Drivers!$C$824)*(1+Drivers!$D$824) -> 10230.981 | I29: =(1-Drivers!$I$810)*(Drivers!$C$23*Drivers!$C$17) + (Drivers!$I$810-Drivers!$I$816)*(Drivers!$C$23*Drivers!$C$17)*(1+Drivers!$C$824) + Drivers!$I$816*(Drivers!$C$23*Drivers!$C$17)*(1+Drivers!$C$824)*(1+Drivers!$D$824) -> 10480.517 | J29: =(1-Drivers!$J$810)*(Drivers!$C$23*Drivers!$C$17) + (Drivers!$J$810-Drivers!$J$816)*(Drivers!$C$23*Drivers!$C$17)*(1+Drivers!$C$824) + Drivers!$J$816*(Drivers!$C$23*Drivers!$C$17)*(1+Drivers!$C$824)*(1+Drivers!$D$824) -> 10480.517 | K29: =(1-Drivers!$K$810)*(Drivers!$C$23*Drivers!$C$17) + (Drivers!$K$810-Drivers!$K$816)*(Drivers!$C$23*Drivers!$C$17)*(1+Drivers!$C$824) + Drivers!$K$816*(Drivers!$C$23*Drivers!$C$17)*(1+Drivers!$C$824)*(1+Drivers!$D$824) -> 10480.517 | L29: =(1-Drivers!$L$810)*(Drivers!$C$23*Drivers!$C$17) + (Drivers!$L$810-Drivers!$L$816)*(Drivers!$C$23*Drivers!$C$17)*(1+Drivers!$C$824) + Drivers!$L$816*(Drivers!$C$23*Drivers!$C$17)*(1+Drivers!$C$824)*(1+Drivers!$D$824) -> 10480.517 | M29: =(1-Drivers!$M$810)*(Drivers!$C$23*Drivers!$C$17) + (Drivers!$M$810-Drivers!$M$816)*(Drivers!$C$23*Drivers!$C$17)*(1+Drivers!$C$824) + Drivers!$M$816*(Drivers!$C$23*Drivers!$C$17)*(1+Drivers!$C$824)*(1+Drivers!$D$824) -> 10480.517 | N29: =(1-Drivers!$N$810)*(Drivers!$C$23*Drivers!$C$17) + (Drivers!$N$810-Drivers!$N$816)*(Drivers!$C$23*Drivers!$C$17)*(1+Drivers!$C$824) + Drivers!$N$816*(Drivers!$C$23*Drivers!$C$17)*(1+Drivers!$C$824)*(1+Drivers!$D$824) -> 10480.517
C30: Cohort 2022 rate | D30: =(1-Drivers!$D$811)*(Drivers!$C$23*Drivers!$C$18) + (Drivers!$D$811-Drivers!$D$817)*(Drivers!$C$23*Drivers!$C$18)*(1+Drivers!$C$825) + Drivers!$D$817*(Drivers!$C$23*Drivers!$C$18)*(1+Drivers!$C$825)*(1+Drivers!$D$825) -> 8918.64 | E30: =(1-Drivers!$E$811)*(Drivers!$C$23*Drivers!$C$18) + (Drivers!$E$811-Drivers!$E$817)*(Drivers!$C$23*Drivers!$C$18)*(1+Drivers!$C$825) + Drivers!$E$817*(Drivers!$C$23*Drivers!$C$18)*(1+Drivers!$C$825)*(1+Drivers!$D$825) -> 10018.606 | F30: =(1-Drivers!$F$811)*(Drivers!$C$23*Drivers!$C$18) + (Drivers!$F$811-Drivers!$F$817)*(Drivers!$C$23*Drivers!$C$18)*(1+Drivers!$C$825) + Drivers!$F$817*(Drivers!$C$23*Drivers!$C$18)*(1+Drivers!$C$825)*(1+Drivers!$D$825) -> 10568.588 | G30: =(1-Drivers!$G$811)*(Drivers!$C$23*Drivers!$C$18) + (Drivers!$G$811-Drivers!$G$817)*(Drivers!$C$23*Drivers!$C$18)*(1+Drivers!$C$825) + Drivers!$G$817*(Drivers!$C$23*Drivers!$C$18)*(1+Drivers!$C$825)*(1+Drivers!$D$825) -> 10568.588 | H30: =(1-Drivers!$H$811)*(Drivers!$C$23*Drivers!$C$18) + (Drivers!$H$811-Drivers!$H$817)*(Drivers!$C$23*Drivers!$C$18)*(1+Drivers!$C$825) + Drivers!$H$817*(Drivers!$C$23*Drivers!$C$18)*(1+Drivers!$C$825)*(1+Drivers!$D$825) -> 10568.588 | I30: =(1-Drivers!$I$811)*(Drivers!$C$23*Drivers!$C$18) + (Drivers!$I$811-Drivers!$I$817)*(Drivers!$C$23*Drivers!$C$18)*(1+Drivers!$C$825) + Drivers!$I$817*(Drivers!$C$23*Drivers!$C$18)*(1+Drivers!$C$825)*(1+Drivers!$D$825) -> 10568.588 | J30: =(1-Drivers!$J$811)*(Drivers!$C$23*Drivers!$C$18) + (Drivers!$J$811-Drivers!$J$817)*(Drivers!$C$23*Drivers!$C$18)*(1+Drivers!$C$825) + Drivers!$J$817*(Drivers!$C$23*Drivers!$C$18)*(1+Drivers!$C$825)*(1+Drivers!$D$825) -> 10674.274 | K30: =(1-Drivers!$K$811)*(Drivers!$C$23*Drivers!$C$18) + (Drivers!$K$811-Drivers!$K$817)*(Drivers!$C$23*Drivers!$C$18)*(1+Drivers!$C$825) + Drivers!$K$817*(Drivers!$C$23*Drivers!$C$18)*(1+Drivers!$C$825)*(1+Drivers!$D$825) -> 10779.96 | L30: =(1-Drivers!$L$811)*(Drivers!$C$23*Drivers!$C$18) + (Drivers!$L$811-Drivers!$L$817)*(Drivers!$C$23*Drivers!$C$18)*(1+Drivers!$C$825) + Drivers!$L$817*(Drivers!$C$23*Drivers!$C$18)*(1+Drivers!$C$825)*(1+Drivers!$D$825) -> 10779.96 | M30: =(1-Drivers!$M$811)*(Drivers!$C$23*Drivers!$C$18) + (Drivers!$M$811-Drivers!$M$817)*(Drivers!$C$23*Drivers!$C$18)*(1+Drivers!$C$825) + Drivers!$M$817*(Drivers!$C$23*Drivers!$C$18)*(1+Drivers!$C$825)*(1+Drivers!$D$825) -> 10779.96 | N30: =(1-Drivers!$N$811)*(Drivers!$C$23*Drivers!$C$18) + (Drivers!$N$811-Drivers!$N$817)*(Drivers!$C$23*Drivers!$C$18)*(1+Drivers!$C$825) + Drivers!$N$817*(Drivers!$C$23*Drivers!$C$18)*(1+Drivers!$C$825)*(1+Drivers!$D$825) -> 10779.96
C31: Cohort 2023 rate | D31: =(1-Drivers!$D$812)*(Drivers!$C$23*Drivers!$C$19) + (Drivers!$D$812-Drivers!$D$818)*(Drivers!$C$23*Drivers!$C$19)*(1+Drivers!$C$826) + Drivers!$D$818*(Drivers!$C$23*Drivers!$C$19)*(1+Drivers!$C$826)*(1+Drivers!$D$826) -> 9290.25 | E31: =(1-Drivers!$E$812)*(Drivers!$C$23*Drivers!$C$19) + (Drivers!$E$812-Drivers!$E$818)*(Drivers!$C$23*Drivers!$C$19)*(1+Drivers!$C$826) + Drivers!$E$818*(Drivers!$C$23*Drivers!$C$19)*(1+Drivers!$C$826)*(1+Drivers!$D$826) -> 9290.25 | F31: =(1-Drivers!$F$812)*(Drivers!$C$23*Drivers!$C$19) + (Drivers!$F$812-Drivers!$F$818)*(Drivers!$C$23*Drivers!$C$19)*(1+Drivers!$C$826) + Drivers!$F$818*(Drivers!$C$23*Drivers!$C$19)*(1+Drivers!$C$826)*(1+Drivers!$D$826) -> 9290.25 | G31: =(1-Drivers!$G$812)*(Drivers!$C$23*Drivers!$C$19) + (Drivers!$G$812-Drivers!$G$818)*(Drivers!$C$23*Drivers!$C$19)*(1+Drivers!$C$826) + Drivers!$G$818*(Drivers!$C$23*Drivers!$C$19)*(1+Drivers!$C$826)*(1+Drivers!$D$826) -> 9832.1812 | H31: =(1-Drivers!$H$812)*(Drivers!$C$23*Drivers!$C$19) + (Drivers!$H$812-Drivers!$H$818)*(Drivers!$C$23*Drivers!$C$19)*(1+Drivers!$C$826) + Drivers!$H$818*(Drivers!$C$23*Drivers!$C$19)*(1+Drivers!$C$826)*(1+Drivers!$D$826) -> 10219.275 | I31: =(1-Drivers!$I$812)*(Drivers!$C$23*Drivers!$C$19) + (Drivers!$I$812-Drivers!$I$818)*(Drivers!$C$23*Drivers!$C$19)*(1+Drivers!$C$826) + Drivers!$I$818*(Drivers!$C$23*Drivers!$C$19)*(1+Drivers!$C$826)*(1+Drivers!$D$826) -> 10219.275 | J31: =(1-Drivers!$J$812)*(Drivers!$C$23*Drivers!$C$19) + (Drivers!$J$812-Drivers!$J$818)*(Drivers!$C$23*Drivers!$C$19)*(1+Drivers!$C$826) + Drivers!$J$818*(Drivers!$C$23*Drivers!$C$19)*(1+Drivers!$C$826)*(1+Drivers!$D$826) -> 10219.275 | K31: =(1-Drivers!$K$812)*(Drivers!$C$23*Drivers!$C$19) + (Drivers!$K$812-Drivers!$K$818)*(Drivers!$C$23*Drivers!$C$19)*(1+Drivers!$C$826) + Drivers!$K$818*(Drivers!$C$23*Drivers!$C$19)*(1+Drivers!$C$826)*(1+Drivers!$D$826) -> 10219.275 | L31: =(1-Drivers!$L$812)*(Drivers!$C$23*Drivers!$C$19) + (Drivers!$L$812-Drivers!$L$818)*(Drivers!$C$23*Drivers!$C$19)*(1+Drivers!$C$826) + Drivers!$L$818*(Drivers!$C$23*Drivers!$C$19)*(1+Drivers!$C$826)*(1+Drivers!$D$826) -> 10321.468 | M31: =(1-Drivers!$M$812)*(Drivers!$C$23*Drivers!$C$19) + (Drivers!$M$812-Drivers!$M$818)*(Drivers!$C$23*Drivers!$C$19)*(1+Drivers!$C$826) + Drivers!$M$818*(Drivers!$C$23*Drivers!$C$19)*(1+Drivers!$C$826)*(1+Drivers!$D$826) -> 10423.66 | N31: =(1-Drivers!$N$812)*(Drivers!$C$23*Drivers!$C$19) + (Drivers!$N$812-Drivers!$N$818)*(Drivers!$C$23*Drivers!$C$19)*(1+Drivers!$C$826) + Drivers!$N$818*(Drivers!$C$23*Drivers!$C$19)*(1+Drivers!$C$826)*(1+Drivers!$D$826) -> 10423.66
C32: Cohort 2024 rate | D32: =(1-Drivers!$D$813)*(Drivers!$C$23*Drivers!$C$20) + (Drivers!$D$813-Drivers!$D$819)*(Drivers!$C$23*Drivers!$C$20)*(1+Drivers!$C$827) + Drivers!$D$819*(Drivers!$C$23*Drivers!$C$20)*(1+Drivers!$C$827)*(1+Drivers!$D$827) -> 9785.73 | E32: =(1-Drivers!$E$813)*(Drivers!$C$23*Drivers!$C$20) + (Drivers!$E$813-Drivers!$E$819)*(Drivers!$C$23*Drivers!$C$20)*(1+Drivers!$C$827) + Drivers!$E$819*(Drivers!$C$23*Drivers!$C$20)*(1+Drivers!$C$827)*(1+Drivers!$D$827) -> 9785.73 | F32: =(1-Drivers!$F$813)*(Drivers!$C$23*Drivers!$C$20) + (Drivers!$F$813-Drivers!$F$819)*(Drivers!$C$23*Drivers!$C$20)*(1+Drivers!$C$827) + Drivers!$F$819*(Drivers!$C$23*Drivers!$C$20)*(1+Drivers!$C$827)*(1+Drivers!$D$827) -> 9785.73 | G32: =(1-Drivers!$G$813)*(Drivers!$C$23*Drivers!$C$20) + (Drivers!$G$813-Drivers!$G$819)*(Drivers!$C$23*Drivers!$C$20)*(1+Drivers!$C$827) + Drivers!$G$819*(Drivers!$C$23*Drivers!$C$20)*(1+Drivers!$C$827)*(1+Drivers!$D$827) -> 9785.73 | H32: =(1-Drivers!$H$813)*(Drivers!$C$23*Drivers!$C$20) + (Drivers!$H$813-Drivers!$H$819)*(Drivers!$C$23*Drivers!$C$20)*(1+Drivers!$C$827) + Drivers!$H$819*(Drivers!$C$23*Drivers!$C$20)*(1+Drivers!$C$827)*(1+Drivers!$D$827) -> 10275.016 | I32: =(1-Drivers!$I$813)*(Drivers!$C$23*Drivers!$C$20) + (Drivers!$I$813-Drivers!$I$819)*(Drivers!$C$23*Drivers!$C$20)*(1+Drivers!$C$827) + Drivers!$I$819*(Drivers!$C$23*Drivers!$C$20)*(1+Drivers!$C$827)*(1+Drivers!$D$827) -> 10275.016 | J32: =(1-Drivers!$J$813)*(Drivers!$C$23*Drivers!$C$20) + (Drivers!$J$813-Drivers!$J$819)*(Drivers!$C$23*Drivers!$C$20)*(1+Drivers!$C$827) + Drivers!$J$819*(Drivers!$C$23*Drivers!$C$20)*(1+Drivers!$C$827)*(1+Drivers!$D$827) -> 10275.016 | K32: =(1-Drivers!$K$813)*(Drivers!$C$23*Drivers!$C$20) + (Drivers!$K$813-Drivers!$K$819)*(Drivers!$C$23*Drivers!$C$20)*(1+Drivers!$C$827) + Drivers!$K$819*(Drivers!$C$23*Drivers!$C$20)*(1+Drivers!$C$827)*(1+Drivers!$D$827) -> 10275.016 | L32: =(1-Drivers!$L$813)*(Drivers!$C$23*Drivers!$C$20) + (Drivers!$L$813-Drivers!$L$819)*(Drivers!$C$23*Drivers!$C$20)*(1+Drivers!$C$827) + Drivers!$L$819*(Drivers!$C$23*Drivers!$C$20)*(1+Drivers!$C$827)*(1+Drivers!$D$827) -> 10275.016 | M32: =(1-Drivers!$M$813)*(Drivers!$C$23*Drivers!$C$20) + (Drivers!$M$813-Drivers!$M$819)*(Drivers!$C$23*Drivers!$C$20)*(1+Drivers!$C$827) + Drivers!$M$819*(Drivers!$C$23*Drivers!$C$20)*(1+Drivers!$C$827)*(1+Drivers!$D$827) -> 10377.767 | N32: =(1-Drivers!$N$813)*(Drivers!$C$23*Drivers!$C$20) + (Drivers!$N$813-Drivers!$N$819)*(Drivers!$C$23*Drivers!$C$20)*(1+Drivers!$C$827) + Drivers!$N$819*(Drivers!$C$23*Drivers!$C$20)*(1+Drivers!$C$827)*(1+Drivers!$D$827) -> 10480.517
C33: Cohort 2025 rate | D33: =(1-Drivers!$D$814)*(Drivers!$C$23*Drivers!$C$21) + (Drivers!$D$814-Drivers!$D$820)*(Drivers!$C$23*Drivers!$C$21)*(1+Drivers!$C$828) + Drivers!$D$820*(Drivers!$C$23*Drivers!$C$21)*(1+Drivers!$C$828)*(1+Drivers!$D$828) -> 10033.47 | E33: =(1-Drivers!$E$814)*(Drivers!$C$23*Drivers!$C$21) + (Drivers!$E$814-Drivers!$E$820)*(Drivers!$C$23*Drivers!$C$21)*(1+Drivers!$C$828) + Drivers!$E$820*(Drivers!$C$23*Drivers!$C$21)*(1+Drivers!$C$828)*(1+Drivers!$D$828) -> 10033.47 | F33: =(1-Drivers!$F$814)*(Drivers!$C$23*Drivers!$C$21) + (Drivers!$F$814-Drivers!$F$820)*(Drivers!$C$23*Drivers!$C$21)*(1+Drivers!$C$828) + Drivers!$F$820*(Drivers!$C$23*Drivers!$C$21)*(1+Drivers!$C$828)*(1+Drivers!$D$828) -> 10033.47 | G33: =(1-Drivers!$G$814)*(Drivers!$C$23*Drivers!$C$21) + (Drivers!$G$814-Drivers!$G$820)*(Drivers!$C$23*Drivers!$C$21)*(1+Drivers!$C$828) + Drivers!$G$820*(Drivers!$C$23*Drivers!$C$21)*(1+Drivers!$C$828)*(1+Drivers!$D$828) -> 10033.47 | H33: =(1-Drivers!$H$814)*(Drivers!$C$23*Drivers!$C$21) + (Drivers!$H$814-Drivers!$H$820)*(Drivers!$C$23*Drivers!$C$21)*(1+Drivers!$C$828) + Drivers!$H$820*(Drivers!$C$23*Drivers!$C$21)*(1+Drivers!$C$828)*(1+Drivers!$D$828) -> 10117.082 | I33: =(1-Drivers!$I$814)*(Drivers!$C$23*Drivers!$C$21) + (Drivers!$I$814-Drivers!$I$820)*(Drivers!$C$23*Drivers!$C$21)*(1+Drivers!$C$828) + Drivers!$I$820*(Drivers!$C$23*Drivers!$C$21)*(1+Drivers!$C$828)*(1+Drivers!$D$828) -> 10535.144 | J33: =(1-Drivers!$J$814)*(Drivers!$C$23*Drivers!$C$21) + (Drivers!$J$814-Drivers!$J$820)*(Drivers!$C$23*Drivers!$C$21)*(1+Drivers!$C$828) + Drivers!$J$820*(Drivers!$C$23*Drivers!$C$21)*(1+Drivers!$C$828)*(1+Drivers!$D$828) -> 10535.144 | K33: =(1-Drivers!$K$814)*(Drivers!$C$23*Drivers!$C$21) + (Drivers!$K$814-Drivers!$K$820)*(Drivers!$C$23*Drivers!$C$21)*(1+Drivers!$C$828) + Drivers!$K$820*(Drivers!$C$23*Drivers!$C$21)*(1+Drivers!$C$828)*(1+Drivers!$D$828) -> 10535.144 | L33: =(1-Drivers!$L$814)*(Drivers!$C$23*Drivers!$C$21) + (Drivers!$L$814-Drivers!$L$820)*(Drivers!$C$23*Drivers!$C$21)*(1+Drivers!$C$828) + Drivers!$L$820*(Drivers!$C$23*Drivers!$C$21)*(1+Drivers!$C$828)*(1+Drivers!$D$828) -> 10535.144 | M33: =(1-Drivers!$M$814)*(Drivers!$C$23*Drivers!$C$21) + (Drivers!$M$814-Drivers!$M$820)*(Drivers!$C$23*Drivers!$C$21)*(1+Drivers!$C$828) + Drivers!$M$820*(Drivers!$C$23*Drivers!$C$21)*(1+Drivers!$C$828)*(1+Drivers!$D$828) -> 10640.495 | N33: =(1-Drivers!$N$814)*(Drivers!$C$23*Drivers!$C$21) + (Drivers!$N$814-Drivers!$N$820)*(Drivers!$C$23*Drivers!$C$21)*(1+Drivers!$C$828) + Drivers!$N$820*(Drivers!$C$23*Drivers!$C$21)*(1+Drivers!$C$828)*(1+Drivers!$D$828) -> 10745.846
C34: Legacy base rate | D34: =Drivers!$C$22 -> 8300 | E34: =Drivers!$C$22 -> 8300 | F34: =Drivers!$C$22 -> 8300 | G34: =Drivers!$C$22 -> 8300 | H34: =Drivers!$C$22 -> 8300 | I34: =Drivers!$C$22 -> 8300 | J34: =Drivers!$C$22 -> 8300 | K34: =Drivers!$C$22 -> 8300 | ... N34: =Drivers!$C$22 -> 8300
C36: REVENUE BY COHORT (reference only v36; D43 NO LONGER sums these — see new engine rows 55-68) | D36: 2025A | E36: 2026E | F36: 2027E | G36: 2028E | H36: 2029E | I36: 2030E | J36: 2031E | K36: 2032E | L36: 2033E | M36: 2034E | N36: 2035E
C37: Cohort 2021 rev | D37: =D21*D29/1000000 -> 199.62889 | E37: =E21*E29/1000000 -> 199.62889 | F37: =F21*F29/1000000 -> 199.62889 | G37: =G21*G29/1000000 -> 199.62889 | H37: =H21*H29/1000000 -> 204.61961 | I37: =I21*I29/1000000 -> 209.61034 | J37: =J21*J29/1000000 -> 211.70644 | K37: =K21*K29/1000000 -> 213.8235 | ... N37: =N21*N29/1000000 -> 220.30257
C38: Cohort 2022 rev | D38: =D22*D30/1000000 -> 164.99484 | E38: =E22*E30/1000000 -> 185.3442 | F38: =F22*F30/1000000 -> 195.51889 | G38: =G22*G30/1000000 -> 195.51889 | H38: =H22*H30/1000000 -> 195.51889 | I38: =I22*I30/1000000 -> 195.51889 | J38: =J22*J30/1000000 -> 199.44881 | K38: =K22*K30/1000000 -> 203.43779 | ... N38: =N22*N30/1000000 -> 209.60216
C39: Cohort 2023 rev | D39: =D23*D31/1000000 -> 173.72768 | E39: =E23*E31/1000000 -> 173.72768 | F39: =F23*F31/1000000 -> 173.72768 | G39: =G23*G31/1000000 -> 183.86179 | H39: =H23*H31/1000000 -> 191.10044 | I39: =I23*I31/1000000 -> 191.10044 | J39: =J23*J31/1000000 -> 193.01145 | K39: =K23*K31/1000000 -> 194.94156 | ... N39: =N23*N31/1000000 -> 204.86546
C40: Cohort 2024 rev | D40: =D24*D32/1000000 -> 189.84316 | E40: =E24*E32/1000000 -> 189.84316 | F40: =F24*F32/1000000 -> 189.84316 | G40: =G24*G32/1000000 -> 189.84316 | H40: =H24*H32/1000000 -> 199.33532 | I40: =I24*I32/1000000 -> 199.33532 | J40: =J24*J32/1000000 -> 201.32867 | K40: =K24*K32/1000000 -> 203.34196 | ... N40: =N24*N32/1000000 -> 213.69349
C41: Cohort 2025 rev | D41: =D25*D33/1000000 -> 215.71961 | E41: =E25*E33/1000000 -> 215.71961 | F41: =F25*F33/1000000 -> 215.71961 | G41: =G25*G33/1000000 -> 215.71961 | H41: =H25*H33/1000000 -> 217.51727 | I41: =I25*I33/1000000 -> 226.50559 | J41: =J25*J33/1000000 -> 228.77064 | K41: =K25*K33/1000000 -> 231.05835 | ... N41: =N25*N33/1000000 -> 242.82084
C42: Base fleet rev | D42: =D26*D34/1000000 -> 20.6919 | E42: =E26*E34/1000000 -> 20.6919 | F42: =F26*F34/1000000 -> 20.6919 | G42: =G26*G34/1000000 -> 20.6919 | H42: =H26*H34/1000000 -> 20.6919 | I42: =I26*I34/1000000 -> 20.6919 | J42: =J26*J34/1000000 -> 20.898819 | K42: =K26*K34/1000000 -> 21.107807 | ... N42: =N26*N34/1000000 -> 21.747395
A43: x | C43: LEGACY COHORT REVENUE TOTAL | D43: =D65 -> 954.2 | E43: =E65 -> 980.16565 | F43: =F65 -> 1004.0025 | G43: =G65 -> 1027.6065 | H43: =H65 -> 1042.0861 | I43: =I65 -> 1044.9995 | J43: =J65 -> 1045.005 | K43: =K65 -> 1048.9927 | ... N43: =N65 -> 1061.0243
A44: x | C44: CALIBRATION CHECK: 2025A vs target | D44: =D43 -> 954.2 | E44: =Drivers!$C$45 -> 954.2 | F44: =D44-E44 -> 0 | P44: v36: delta MUST be ~0 (D65 anchored to Drivers!C45; no calibration factor needed).
C46: IMPLIED LPI (OUTPUT ROW, v23): year-over-year revenue-per-car growth. Should = Terminal_LPI (2%) in every terminal year since car counts grow separately at Terminal_fleet_growth. | D46: n/a | E46: n/a | F46: n/a | G46: n/a | H46: n/a | I46: n/a | J46: =IFERROR((J43/SUM(J21:J26))/(I43/SUM(I21:I26))-1, 0) -> -0.0098957236 | K46: =IFERROR((K43/SUM(K21:K26))/(J43/SUM(J21:J26))-1, 0) -> -0.0061228446 | L46: =IFERROR((L43/SUM(L21:L26))/(K43/SUM(K21:K26))-1, 0) -> -0.0061300157 | M46: =IFERROR((M43/SUM(M21:M26))/(L43/SUM(L21:L26))-1, 0) -> -0.0061300021 | N46: =IFERROR((N43/SUM(N21:N26))/(M43/SUM(M21:M26))-1, 0) -> -0.0061300021
C48: v23 (2026-09-28): terminal years 2031E-2035E — cohort rates (rows 29-33) compound at Terminal_LPI; cars (rows 21-26) compound at Terminal_fleet_growth. Legacy base rate row 34 held flat at Drivers!C22 (existing mechanic). Implied LPI output row 46 now measures revenue-per-car YoY growth to isolate LPI from fleet-count growth.
B50: 2024A=0 (no modeled cohort R1 lands in 2024) | C50: Cars renewing per year (v34, derived) | D50: =Drivers!$C11*Drivers!$D$810+Drivers!$C12*Drivers!$D$811+Drivers!$C13*Drivers!$D$812+Drivers!$C14*Drivers!$D$813+Drivers!$C15*Drivers!$D$814+Drivers!$C11*Drivers!$D$816+Drivers!$C12*Drivers!$D$817+Drivers!$C13*Drivers!$D$818+Drivers!$C14*Drivers!$D$819+Drivers!$C15*Drivers!$D$820 -> 20000 | E50: =Drivers!$C11*(Drivers!$E$810-Drivers!$D$810)+Drivers!$C12*(Drivers!$E$811-Drivers!$D$811)+Drivers!$C13*(Drivers!$E$812-Drivers!$D$812)+Drivers!$C14*(Drivers!$E$813-Drivers!$D$813)+Drivers!$C15*(Drivers!$E$814-Drivers!$D$814)+Drivers!$C11*(Drivers!$E$816-Drivers!$D$816)+Drivers!$C12*(Drivers!$E$817-Drivers!$D$817)+Drivers!$C13*(Drivers!$E$818-Drivers!$D$818)+Drivers!$C14*(Drivers!$E$819-Drivers!$D$819)+Drivers!$C15*(Drivers!$E$820-Drivers!$D$820) -> 12333.333 | F50: =Drivers!$C11*(Drivers!$F$810-Drivers!$E$810)+Drivers!$C12*(Drivers!$F$811-Drivers!$E$811)+Drivers!$C13*(Drivers!$F$812-Drivers!$E$812)+Drivers!$C14*(Drivers!$F$813-Drivers!$E$813)+Drivers!$C15*(Drivers!$F$814-Drivers!$E$814)+Drivers!$C11*(Drivers!$F$816-Drivers!$E$816)+Drivers!$C12*(Drivers!$F$817-Drivers!$E$817)+Drivers!$C13*(Drivers!$F$818-Drivers!$E$818)+Drivers!$C14*(Drivers!$F$819-Drivers!$E$819)+Drivers!$C15*(Drivers!$F$820-Drivers!$E$820) -> 6166.6667 | G50: =Drivers!$C11*(Drivers!$G$810-Drivers!$F$810)+Drivers!$C12*(Drivers!$G$811-Drivers!$F$811)+Drivers!$C13*(Drivers!$G$812-Drivers!$F$812)+Drivers!$C14*(Drivers!$G$813-Drivers!$F$813)+Drivers!$C15*(Drivers!$G$814-Drivers!$F$814)+Drivers!$C11*(Drivers!$G$816-Drivers!$F$816)+Drivers!$C12*(Drivers!$G$817-Drivers!$F$817)+Drivers!$C13*(Drivers!$G$818-Drivers!$F$818)+Drivers!$C14*(Drivers!$G$819-Drivers!$F$819)+Drivers!$C15*(Drivers!$G$820-Drivers!$F$820) -> 10908.333 | H50: =Drivers!$C11*(Drivers!$H$810-Drivers!$G$810)+Drivers!$C12*(Drivers!$H$811-Drivers!$G$811)+Drivers!$C13*(Drivers!$H$812-Drivers!$G$812)+Drivers!$C14*(Drivers!$H$813-Drivers!$G$813)+Drivers!$C15*(Drivers!$H$814-Drivers!$G$814)+Drivers!$C11*(Drivers!$H$816-Drivers!$G$816)+Drivers!$C12*(Drivers!$H$817-Drivers!$G$817)+Drivers!$C13*(Drivers!$H$818-Drivers!$G$818)+Drivers!$C14*(Drivers!$H$819-Drivers!$G$819)+Drivers!$C15*(Drivers!$H$820-Drivers!$G$820) -> 40775 | I50: =Drivers!$C11*(Drivers!$I$810-Drivers!$H$810)+Drivers!$C12*(Drivers!$I$811-Drivers!$H$811)+Drivers!$C13*(Drivers!$I$812-Drivers!$H$812)+Drivers!$C14*(Drivers!$I$813-Drivers!$H$813)+Drivers!$C15*(Drivers!$I$814-Drivers!$H$814)+Drivers!$C11*(Drivers!$I$816-Drivers!$H$816)+Drivers!$C12*(Drivers!$I$817-Drivers!$H$817)+Drivers!$C13*(Drivers!$I$818-Drivers!$H$818)+Drivers!$C14*(Drivers!$I$819-Drivers!$H$819)+Drivers!$C15*(Drivers!$I$820-Drivers!$H$820) -> 27916.667 | P50: v34: derived from Drivers term-by-year block (rows 788-820). Formula: sum over 5 cohorts of (cars × delta_R1_frac + cars × delta_R2_frac). 2024A reported as 0 since no modeled cohort R1 lands in 2024 (Cohort 2021 R1 = 2025 under term-driven).
...

Sheet Acquired Pool
C2: ="Financial Statement Model - "&Cover!$D$5 -> Financial Statement Model - GATX Corporation
C3: $ mm except per share
C5: Company name | D5: =Cover!$D$5 -> GATX Corporation
C6: Ticker | D6: =Cover!$D$6 -> GATX
C7: Circ break 1=off, 0=on | D7: =Cover!$D$7 -> 1
C8: Latest closing share price | D8: =Cover!$D$8 -> 162.78
C9: Share price date | D9: =Cover!$D$9 -> 46303
C10: Latest fiscal year end | D10: =Cover!$D$10 -> 46022
C11: Shares outstanding (millions) | D11: =Cover!$D$11 -> 35.8
C13: ACQUIRED POOL (Wells Fargo) — carry blended rate forward, reprice expiring fraction
C15: Base: GABX H1 2026 revenue $271.5M half-year (10-Q Note 7 p.11). Full-year 2026E = 271.5 + Q2 run rate × 2.
C16: Blended rate rises with LPI on expiring fraction only. Cars held flat pending disclosure.
D18: 2025A | E18: 2026E | F18: 2027E | G18: 2028E | H18: 2029E | I18: 2030E | J18: 2031E | K18: 2032E | L18: 2033E | M18: 2034E | N18: 2035E
C19: Acquired pool cars | D19: 0 | E19: =Drivers!$C$25 -> 98535 | F19: =Drivers!$C$25 -> 98535 | G19: =Drivers!$C$25 -> 98535 | H19: =Drivers!$C$25 -> 98535 | I19: =Drivers!$C$25 -> 98535 | J19: =I19*(1+Drivers!$C$705) -> 99520.35 | K19: =J19*(1+Drivers!$C$705) -> 100515.55 | L19: =K19*(1+Drivers!$C$705) -> 101520.71 | M19: =L19*(1+Drivers!$C$705) -> 102535.92 | N19: =M19*(1+Drivers!$C$705) -> 103561.28
C20: Implied rate at close ($/car/yr) = H1 rev × 2 / cars | D20: 0 | E20: =Drivers!$C$26*2*1000000/Drivers!$C$25 -> 5510.7322 | F20: =E20 -> 5510.7322 | G20: =E20 -> 5510.7322 | H20: =E20 -> 5510.7322 | I20: =E20 -> 5510.7322 | J20: =I20 -> 5510.7322 | K20: =J20 -> 5510.7322 | L20: =K20 -> 5510.7322 | M20: =L20 -> 5510.7322 | N20: =M20 -> 5510.7322
C21: Fraction expiring this year | D21: 0 | E21: =Drivers!$C$176 -> 0.25 | F21: =Drivers!$C$176 -> 0.25 | G21: =Drivers!$C$176 -> 0.25 | H21: =Drivers!$C$176 -> 0.25 | I21: =Drivers!$C$176 -> 0.25 | J21: =Drivers!$C$176 -> 0.25 | K21: =Drivers!$C$176 -> 0.25 | L21: =Drivers!$C$176 -> 0.25 | ... N21: =Drivers!$C$176 -> 0.25
C22: Blended rate ($/car/yr) | D22: 0 | E22: =E20 -> 5510.7322 | F22: =E22*(1+Drivers!$C$33*F21) -> 5717.3847 | G22: =F22*(1+Drivers!$C$34*G21) -> 5860.3193 | H22: =G22*(1+Drivers!$C$35*H21) -> 5933.5733 | I22: =H22*(1+Drivers!$C$36*I21) -> 5903.9054 | J22: =I22*(1+Drivers!$C$704*J21) -> 5933.425 | K22: =J22*(1+Drivers!$C$704*K21) -> 5963.0921 | L22: =K22*(1+Drivers!$C$704*L21) -> 5992.9075 | M22: =L22*(1+Drivers!$C$704*M21) -> 6022.8721 | N22: =M22*(1+Drivers!$C$704*N21) -> 6052.9864
A23: x | C23: ACQUIRED POOL REVENUE ($M) | D23: =D19*D22/1000000 -> 0 | E23: =E19*E22/1000000 -> 543 | F23: =F19*F22/1000000 -> 563.3625 | G23: =G19*G22/1000000 -> 577.44656 | H23: =H19*H22/1000000 -> 584.66464 | I23: =I19*I22/1000000 -> 581.74132 | J23: =J19*J22/1000000 -> 590.49653 | K23: =K19*K22/1000000 -> 599.3835 | ... N23: =N19*N22/1000000 -> 626.85499 | P23: FY2026E gate: should be ~$543M (H1 $271.5 × 2 = $543M; Q2 was $136.6M × 2 = $273M for H2)
C25: v17 Item 2 (2026-09-26): 2031E-2035E revenue overrides pool mechanics and grows at Terminal_g (Drivers!B397). Rationale: pool LPI cycle completes by ~2029E; terminal state grows at g by construction.
C27: v23 (2026-09-28): terminal years 2031E-2035E — cars row 19 compounds at Terminal_fleet_growth; blended rate row 22 compounds at Terminal_LPI × fraction_expiring (same mechanic as 2026-2030 but with terminal LPI). Revenue row 23 is cars × rate / 1e6 (pool mechanics restored, v17 override retired).
A29: x | C29: SENSITIVITY: 2027E acquired-pool revenue and 2027E EPS at C176 = 20% / 25% / 30% (v26 1c)
C30: Fraction expiring | D30: 0.2 | E30: 0.25 | F30: 0.3
C31: 2027E blended rate ($/car/yr) | D31: =$E$20*(1+Drivers!$C$33*D30) -> 5676.0542 | E31: =$E$20*(1+Drivers!$C$33*E30) -> 5717.3847 | F31: =$E$20*(1+Drivers!$C$33*F30) -> 5758.7152
C32: 2027E acquired-pool revenue ($M) | D32: =$F$19*D31/1000000 -> 559.29 | E32: =$F$19*E31/1000000 -> 563.3625 | F32: =$F$19*F31/1000000 -> 567.435
C33: 2027E EPS ($/sh, model base + delta rev × (1-tax) / shares) | D33: ='3 Statement Forecast'!$F$33+(D32-$E$32)*(1-Drivers!$C$274)/Drivers!$C$277 -> 10.085393 | E33: ='3 Statement Forecast'!$F$33+(E32-$E$32)*(1-Drivers!$C$274)/Drivers!$C$277 -> 10.17606 | F33: ='3 Statement Forecast'!$F$33+(F32-$E$32)*(1-Drivers!$C$274)/Drivers!$C$277 -> 10.266727
C34: Note: base column (E) uses C176=0.25 same as model driver; F and D show effect of ±5pp.
A35: x | C35: IDLE-FILL MECHANISM (v38 Phase B, switch=Drivers!C763). Default OFF. Util rises 97%->99% over 2026E-2030E when switch=1.
C36: Idle_fill_incremental_cars | E36: ='Acquired Pool'!E19*(Drivers!$C$764-Drivers!$C$769)*Drivers!$C$763 -> 0 | F36: ='Acquired Pool'!F19*(Drivers!$C$765-Drivers!$C$769)*Drivers!$C$763 -> 0 | G36: ='Acquired Pool'!G19*(Drivers!$C$766-Drivers!$C$769)*Drivers!$C$763 -> 0 | H36: ='Acquired Pool'!H19*(Drivers!$C$767-Drivers!$C$769)*Drivers!$C$763 -> 0 | I36: ='Acquired Pool'!I19*(Drivers!$C$768-Drivers!$C$769)*Drivers!$C$763 -> 0
C37: Idle_fill_incremental_rev_$M | E37: ='Acquired Pool'!E36*'Acquired Pool'!E22/1000000 -> 0 | F37: ='Acquired Pool'!F36*'Acquired Pool'!F22/1000000 -> 0 | G37: ='Acquired Pool'!G36*'Acquired Pool'!G22/1000000 -> 0 | H37: ='Acquired Pool'!H36*'Acquired Pool'!H22/1000000 -> 0 | I37: ='Acquired Pool'!I36*'Acquired Pool'!I22/1000000 -> 0
C38: Idle_fill_incremental_maint_$M | E38: ='Acquired Pool'!E37*Drivers!$C$128 -> 0 | F38: ='Acquired Pool'!F37*Drivers!$C$128 -> 0 | G38: ='Acquired Pool'!G37*Drivers!$C$128 -> 0 | H38: ='Acquired Pool'!H37*Drivers!$C$128 -> 0 | I38: ='Acquired Pool'!I37*Drivers!$C$128 -> 0
